Workbook

Sheet Weekly Plan
A1: Weekly Training Plan
A3: Day | B3: Session | C3: Exercise / Activity | D3: Sets | E3: Reps / Duration | F3: Notes | H3: Targets | I3: Goal | J3: Current
A4: Monday | B4: Home Strength A | C4: Pull-Ups | D4: 4 | E4: 5–10 | F4: 1–2 reps in reserve | H4: Protein | I4: 110–130 g/day
A5: Monday | B5: Home Strength A | C5: Bulgarian Split Squat | D5: 4 | E5: 8–15 / leg | H5: Calorie Deficit | I5: 300–500 kcal/day
A6: Monday | B6: Home Strength A | C6: Push-Up Variation | D6: 4 | E6: 8–20 | H6: Weight Loss | I6: 0.3–0.5 kg/week
A7: Monday | B7: Home Strength A | C7: Suspension Hamstring Curl | D7: 3 | E7: 8–15 | H7: Daily Steps | I7: 7,000–10,000
A8: Monday | B8: Home Strength A | C8: KB Overhead Press | D8: 3 | E8: 6–12 / side | H8: Sleep | I8: 7.5–9 hours
A9: Monday | B9: Home Strength A | C9: Hanging Knee Raise / Body Saw | D9: 3 | E9: 8–15 | H9: Rucking | I9: 1–3 sessions/week
A10: Tuesday | B10: Rucking / Walking | C10: Rucking | E10: 15–30 min | F10: 10–12 kg
A11: Tuesday | B11: Rucking / Walking | C11: Total Daily Steps | E11: 7,000–10,000
A12: Wednesday | B12: Recovery | C12: Easy Walking / Mobility | E12: Optional
A13: Thursday | B13: Home Strength B | C13: Suspension Row | D13: 4 | E13: 8–15
A14: Thursday | B14: Home Strength B | C14: Single-Leg Romanian Deadlift | D14: 4 | E14: 8–15 / leg
A15: Thursday | B15: Home Strength B | C15: Pike Push-Up | D15: 4 | E15: 6–15
A16: Thursday | B16: Home Strength B | C16: Reverse Lunge / Step-Up | D16: 3 | E16: 10–15 / leg
A17: Thursday | B17: Home Strength B | C17: Kettlebell Swing | D17: 5–10 | E17: 10–15 | F17: Do not train to failure
A18: Thursday | B18: Home Strength B | C18: Suspension Face Pull / Reverse Fly | D18: 3 | E18: 12–20
A19: Friday | B19: Recovery | C19: Easy Walking / Mobility | E19: Optional
A20: Saturday | B20: Full-Body Gym | C20: Squat / Leg Press | D20: 3–4 | E20: 5–8
A21: Saturday | B21: Full-Body Gym | C21: Bench Press / Chest Press / Dips | D21: 3–4 | E21: 5–10
A22: Saturday | B22: Full-Body Gym | C22: Romanian Deadlift / Trap-Bar Deadlift | D22: 3 | E22: 5–10
A23: Saturday | B23: Full-Body Gym | C23: Weighted Pull-Up / Heavy Row | D23: 3–4 | E23: 6–10
A24: Saturday | B24: Full-Body Gym | C24: Lateral Raise | D24: 3 | E24: 10–20
A25: Saturday | B25: Full-Body Gym | C25: Optional Curl + Triceps | D25: 2–3 | E25: 8–15
A26: Sunday | B26: Recovery | C26: Rest / Easy Walking / Easy Ruck | E26: 15–30 min | F26: Optional

Sheet Training Log
A1: Training Log
A3: Date | B3: Program Week | C3: Category | D3: Workout Name | E3: Exercise | F3: Set # | G3: Weight (kg) | H3: Reps | I3: Distance (km) | J3: Duration | K3: RPE | L3: Set Volume | M3: Body Weight (kg) | N3: Notes
A4: 46219 | B4: =IF(A4="","",INT((A4-Settings!$B$4)/7)+1) -> 1 | C4: Strength | D4: Home Strength B | E4: Suspension Row | F4: 1 | H4: 12 | K4: 8 | L4: =IF(OR(G4="",H4=""),"",G4*H4) | M4: 62
A5: 46219 | B5: =IF(A5="","",INT((A5-Settings!$B$4)/7)+1) -> 1 | C5: Strength | D5: Home Strength B | E5: Suspension Row | F5: 2 | H5: 12 | K5: 8 | L5: =IF(OR(G5="",H5=""),"",G5*H5) | M5: 62
A6: 46219 | B6: =IF(A6="","",INT((A6-Settings!$B$4)/7)+1) -> 1 | C6: Strength | D6: Home Strength B | E6: Suspension Row | F6: 3 | H6: 12 | K6: 8 | L6: =IF(OR(G6="",H6=""),"",G6*H6) | M6: 62
A7: 46219 | B7: =IF(A7="","",INT((A7-Settings!$B$4)/7)+1) -> 1 | C7: Strength | D7: Home Strength B | E7: Suspension Row | F7: 4 | H7: 12 | K7: 8 | L7: =IF(OR(G7="",H7=""),"",G7*H7) | M7: 62
A8: 46219 | B8: =IF(A8="","",INT((A8-Settings!$B$4)/7)+1) -> 1 | C8: Conditioning | D8: Fasted Kettlebell Swings | E8: Kettlebell Swing | F8: 1 | G8: 12 | H8: 25 | K8: 7 | L8: =IF(OR(G8="",H8=""),"",G8*H8) -> 300 | M8: 62 | N8: Done while fasted for 20+ hours
A9: 46219 | B9: =IF(A9="","",INT((A9-Settings!$B$4)/7)+1) -> 1 | C9: Conditioning | D9: Fasted Kettlebell Swings | E9: Kettlebell Swing | F9: 2 | G9: 12 | H9: 25 | K9: 7 | L9: =IF(OR(G9="",H9=""),"",G9*H9) -> 300 | M9: 62 | N9: Done while fasted for 20+ hours
A10: 46219 | B10: =IF(A10="","",INT((A10-Settings!$B$4)/7)+1) -> 1 | C10: Strength | D10: Home Strength B | E10: Single-Leg Romanian Deadlift | F10: 1 | G10: 12 | H10: 10 | K10: 8.5 | L10: =IF(OR(G10="",H10=""),"",G10*H10) -> 120 | M10: 62
A11: 46219 | B11: =IF(A11="","",INT((A11-Settings!$B$4)/7)+1) -> 1 | C11: Strength | D11: Home Strength B | E11: Single-Leg Romanian Deadlift | F11: 2 | G11: 12 | H11: 10 | K11: 8.5 | L11: =IF(OR(G11="",H11=""),"",G11*H11) -> 120 | M11: 62
A12: 46219 | B12: =IF(A12="","",INT((A12-Settings!$B$4)/7)+1) -> 1 | C12: Strength | D12: Home Strength B | E12: Single-Leg Romanian Deadlift | F12: 3 | G12: 12 | H12: 10 | K12: 8.5 | L12: =IF(OR(G12="",H12=""),"",G12*H12) -> 120 | M12: 62
A13: 46219 | B13: =IF(A13="","",INT((A13-Settings!$B$4)/7)+1) -> 1 | C13: Strength | D13: Home Strength B | E13: Single-Leg Romanian Deadlift | F13: 4 | G13: 12 | H13: 10 | K13: 8.5 | L13: =IF(OR(G13="",H13=""),"",G13*H13) -> 120 | M13: 62
A14: 46219 | B14: =IF(A14="","",INT((A14-Settings!$B$4)/7)+1) -> 1 | C14: Strength | D14: Home Strength B | E14: Nordic Hamstring Curl | F14: 1 | H14: 8 | K14: 8.5 | L14: =IF(OR(G14="",H14=""),"",G14*H14) | M14: 62
A15: 46219 | B15: =IF(A15="","",INT((A15-Settings!$B$4)/7)+1) -> 1 | C15: Strength | D15: Home Strength B | E15: Pike Push-Up | F15: 1 | H15: 12 | K15: 8.5 | L15: =IF(OR(G15="",H15=""),"",G15*H15) | M15: 62
A16: 46219 | B16: =IF(A16="","",INT((A16-Settings!$B$4)/7)+1) -> 1 | C16: Strength | D16: Home Strength B | E16: Pike Push-Up | F16: 2 | H16: 12 | K16: 8.5 | L16: =IF(OR(G16="",H16=""),"",G16*H16) | M16: 62
A17: 46219 | B17: =IF(A17="","",INT((A17-Settings!$B$4)/7)+1) -> 1 | C17: Strength | D17: Home Strength B | E17: Pike Push-Up | F17: 3 | H17: 12 | K17: 8.5 | L17: =IF(OR(G17="",H17=""),"",G17*H17) | M17: 62
A18: 46219 | B18: =IF(A18="","",INT((A18-Settings!$B$4)/7)+1) -> 1 | C18: Strength | D18: Home Strength B | E18: Pike Push-Up | F18: 4 | H18: 12 | K18: 8.5 | L18: =IF(OR(G18="",H18=""),"",G18*H18) | M18: 62
A19: 46219 | B19: =IF(A19="","",INT((A19-Settings!$B$4)/7)+1) -> 1 | C19: Strength | D19: Home Strength B | E19: Reverse Lunge | F19: 1 | H19: 10 | K19: 7 | L19: =IF(OR(G19="",H19=""),"",G19*H19) | M19: 62 | N19: Reps per leg
A20: 46219 | B20: =IF(A20="","",INT((A20-Settings!$B$4)/7)+1) -> 1 | C20: Strength | D20: Home Strength B | E20: Reverse Lunge | F20: 2 | H20: 10 | K20: 7 | L20: =IF(OR(G20="",H20=""),"",G20*H20) | M20: 62 | N20: Reps per leg
A21: 46219 | B21: =IF(A21="","",INT((A21-Settings!$B$4)/7)+1) -> 1 | C21: Strength | D21: Home Strength B | E21: Reverse Lunge | F21: 3 | H21: 10 | K21: 7 | L21: =IF(OR(G21="",H21=""),"",G21*H21) | M21: 62 | N21: Reps per leg
A22: 46219 | B22: =IF(A22="","",INT((A22-Settings!$B$4)/7)+1) -> 1 | C22: Strength | D22: Home Strength B | E22: Kettlebell Swing | F22: 1 | G22: 12 | H22: 15 | K22: 8 | L22: =IF(OR(G22="",H22=""),"",G22*H22) -> 180 | M22: 62
A23: 46219 | B23: =IF(A23="","",INT((A23-Settings!$B$4)/7)+1) -> 1 | C23: Strength | D23: Home Strength B | E23: Kettlebell Swing | F23: 2 | G23: 12 | H23: 15 | K23: 8 | L23: =IF(OR(G23="",H23=""),"",G23*H23) -> 180 | M23: 62
A24: 46219 | B24: =IF(A24="","",INT((A24-Settings!$B$4)/7)+1) -> 1 | C24: Strength | D24: Home Strength B | E24: Kettlebell Swing | F24: 3 | G24: 12 | H24: 15 | K24: 8 | L24: =IF(OR(G24="",H24=""),"",G24*H24) -> 180 | M24: 62
A25: 46219 | B25: =IF(A25="","",INT((A25-Settings!$B$4)/7)+1) -> 1 | C25: Strength | D25: Home Strength B | E25: Kettlebell Swing | F25: 4 | G25: 12 | H25: 15 | K25: 8 | L25: =IF(OR(G25="",H25=""),"",G25*H25) -> 180 | M25: 62
A26: 46219 | B26: =IF(A26="","",INT((A26-Settings!$B$4)/7)+1) -> 1 | C26: Strength | D26: Home Strength B | E26: Suspension Face | F26: 1 | H26: 10 | K26: 7 | L26: =IF(OR(G26="",H26=""),"",G26*H26) | M26: 62
A27: 46219 | B27: =IF(A27="","",INT((A27-Settings!$B$4)/7)+1) -> 1 | C27: Strength | D27: Home Strength B | E27: Suspension Face | F27: 2 | H27: 10 | K27: 7 | L27: =IF(OR(G27="",H27=""),"",G27*H27) | M27: 62
A28: 46219 | B28: =IF(A28="","",INT((A28-Settings!$B$4)/7)+1) -> 1 | C28: Strength | D28: Home Strength B | E28: Suspension Face | F28: 3 | H28: 10 | K28: 7 | L28: =IF(OR(G28="",H28=""),"",G28*H28) | M28: 62
A29: 46221 | B29: =IF(A29="","",INT((A29-Settings!$B$4)/7)+1) -> 1 | C29: Strength | D29: Full-Body Gym | E29: Front Squat | F29: 1 | G29: 40 | H29: 5 | K29: 7 | L29: =IF(OR(G29="",H29=""),"",G29*H29) -> 200 | M29: 61
A30: 46221 | B30: =IF(A30="","",INT((A30-Settings!$B$4)/7)+1) -> 1 | C30: Strength | D30: Full-Body Gym | E30: Front Squat | F30: 2 | G30: 50 | H30: 5 | K30: 7 | L30: =IF(OR(G30="",H30=""),"",G30*H30) -> 250 | M30: 61
A31: 46221 | B31: =IF(A31="","",INT((A31-Settings!$B$4)/7)+1) -> 1 | C31: Strength | D31: Full-Body Gym | E31: Front Squat | F31: 3 | G31: 60 | H31: 5 | K31: 8 | L31: =IF(OR(G31="",H31=""),"",G31*H31) -> 300 | M31: 61
A32: 46221 | B32: =IF(A32="","",INT((A32-Settings!$B$4)/7)+1) -> 1 | C32: Strength | D32: Full-Body Gym | E32: Front Squat | F32: 4 | G32: 70 | H32: 5 | K32: 8 | L32: =IF(OR(G32="",H32=""),"",G32*H32) -> 350 | M32: 61
A33: 46221 | B33: =IF(A33="","",INT((A33-Settings!$B$4)/7)+1) -> 1 | C33: Strength | D33: Full-Body Gym | E33: Front Squat | F33: 5 | G33: 90 | H33: 3 | K33: 8 | L33: =IF(OR(G33="",H33=""),"",G33*H33) -> 270 | M33: 61 | N33: Failed rep at the end
A34: 46221 | B34: =IF(A34="","",INT((A34-Settings!$B$4)/7)+1) -> 1 | C34: Strength | D34: Full-Body Gym | E34: Back Squat | F34: 1 | G34: 100 | H34: 3 | K34: 7.5 | L34: =IF(OR(G34="",H34=""),"",G34*H34) -> 300 | M34: 61 | N34: Get spotted, make it easier for reps
A35: 46221 | B35: =IF(A35="","",INT((A35-Settings!$B$4)/7)+1) -> 1 | C35: Strength | D35: Full-Body Gym | E35: Incline Bench Press | F35: 1 | G35: 35 | H35: 12 | K35: 7 | L35: =IF(OR(G35="",H35=""),"",G35*H35) -> 420 | M35: 61
A36: 46221 | B36: =IF(A36="","",INT((A36-Settings!$B$4)/7)+1) -> 1 | C36: Strength | D36: Full-Body Gym | E36: Chest Press | F36: 1 | G36: 20 | H36: 10 | K36: 6 | L36: =IF(OR(G36="",H36=""),"",G36*H36) -> 200 | M36: 61
A37: 46221 | B37: =IF(A37="","",INT((A37-Settings!$B$4)/7)+1) -> 1 | C37: Strength | D37: Full-Body Gym | E37: Chest Press | F37: 2 | G37: 35 | H37: 7 | K37: 6 | L37: =IF(OR(G37="",H37=""),"",G37*H37) -> 245 | M37: 61
A38: 46221 | B38: =IF(A38="","",INT((A38-Settings!$B$4)/7)+1) -> 1 | C38: Strength | D38: Full-Body Gym | E38: Chest Press | F38: 3 | G38: 35 | H38: 10 | K38: 6 | L38: =IF(OR(G38="",H38=""),"",G38*H38) -> 350 | M38: 61
A39: 46221 | B39: =IF(A39="","",INT((A39-Settings!$B$4)/7)+1) -> 1 | C39: Strength | D39: Full-Body Gym | E39: Chest Press | F39: 4 | G39: 65 | H39: 8 | K39: 8.5 | L39: =IF(OR(G39="",H39=""),"",G39*H39) -> 520 | M39: 61
A40: 46221 | B40: =IF(A40="","",INT((A40-Settings!$B$4)/7)+1) -> 1 | C40: Strength | D40: Full-Body Gym | E40: Chest Press | F40: 5 | G40: 55 | H40: 6 | K40: 8 | L40: =IF(OR(G40="",H40=""),"",G40*H40) -> 330 | M40: 61
A41: 46221 | B41: =IF(A41="","",INT((A41-Settings!$B$4)/7)+1) -> 1 | C41: Strength | D41: Full-Body Gym | E41: Chest Press | F41: 6 | G41: 55 | H41: 7 | K41: 8 | L41: =IF(OR(G41="",H41=""),"",G41*H41) -> 385 | M41: 61
...

Sheet Body Progress
A1: Body & Fat-Loss Progress
A3: Date | B3: Weight (kg) | C3: Waist (cm) | D3: Body Fat % | E3: Daily Steps | F3: Rucking (min) | G3: Calories | H3: Protein (g) | I3: Sleep (hours) | J3: Notes | L3: Summary | M3: Value
L4: Latest Weight | M4: =IFERROR(LOOKUP(2,1/(B4:B203<>""),B4:B203),"")
L5: Starting Weight | M5: =IFERROR(INDEX(B4:B203,MATCH(TRUE,B4:B203<>"",0)),"")
L6: Weight Change | M6: =IF(OR(M4="",M5=""),"",M4-M5)
L7: Average Steps | M7: =IFERROR(AVERAGE(E4:E203),"")
L8: Average Protein | M8: =IFERROR(AVERAGE(H4:H203),"")

Sheet How to Use
A1: How to Use This Workbook
A3: Sheet | B3: Purpose
A4: Weekly Plan | B4: Check the current weekly schedule and exercise targets.
A5: Training Log | B5: Enter one row per set. Program Week and Set Volume calculate automatically.
A6: Body Progress | B6: Log body weight, waist, steps, food, protein, and sleep.
A7: Settings | B7: Change the program start date and targets in one place.
A8: Duration | B8: Enter durations as hh:mm:ss, for example 00:11:36.
A9: Blank fields | B9: Leave irrelevant fields blank; do not type dashes or zeroes.

Sheet Settings
A1: Program Settings
A3: Program Name | B3: Lean Hybrid Athlete v1
A4: Program Start Date | B4: 46217
A5: Target Body Weight (kg) | B5: 56
A6: Target Body Fat | B6: 0.12
A7: Protein Target (g) | B7: 120
A8: Daily Step Target | B8: 10000
